<?xml version="1.0"?>

<robot xmlns:xacro="http://www.ros.org/wiki/xacro" >

    <material name="blue">
      <color rgba="0 0 0.8 1"/>
    </material>
    <material name="white">
      <color rgba="1 1 1 1"/>
    </material>
    <material name="black">
      <color rgba="0 0 0 1"/>
    </material>
    <material name="green">
        <color rgba="0 0.8 0 1"/>
    </material>
    <material name="red">
        <color rgba="1 0 0 1"/>
    </material>

    
    <!--INERTIAL BOX MACRO-->
    <xacro:macro name="inertial_box" params="mass x y z">
        <inertial>
            <origin xyz="0.0 0.0 0.0" rpy="0.0 0.0 0.0"/>
            <mass value="${mass}" />
            <inertia ixx="${(1/12) * mass * (y*y+z*z)}" ixy="0.0" ixz="0.0"
                    iyy="${(1/12) * mass * (x*x+z*z)}" iyz="0.0"
                    izz="${(1/12) * mass * (x*x+y*y)}" />
        </inertial>
    </xacro:macro>
    <!--INERTIAL CYLINDER MACRO-->
    <xacro:macro name="inertial_cylinder" params="mass length radius">
        <inertial>
            <origin xyz="0.0 0.0 0.0" rpy="0.0 0.0 0.0"/>
            <mass value="${mass}" />
            <inertia ixx="${(1/12) * mass * (3*radius*radius + length*length)}" ixy="0.0" ixz="0.0"
                    iyy="${(1/12) * mass * (3*radius*radius + length*length)}" iyz="0.0"
                    izz="${(1/2) * mass * (radius*radius)}" />
        </inertial>
    </xacro:macro>
    <!--INERTIAL SPHERE MACRO-->
    <xacro:macro name="inertial_sphere" params="mass radius">
        <inertial>
            <origin xyz="0.0 0.0 0.0" rpy="0.0 0.0 0.0"/>
            <mass value="${mass}" />
            <inertia ixx="${(2/5) * mass * (radius*radius)}" ixy="0.0" ixz="0.0"
                    iyy="${(2/5) * mass * (radius*radius)}" iyz="0.0"
                    izz="${(2/5) * mass * (radius*radius)}" />
        </inertial>
    </xacro:macro> 

    <!--BASE_LINK-->
    <link name="base_link">

    </link>

    <!--CHASSIS OF THE ROBOT-->
    <link name="chassis_link">
        <visual>
            <geometry>
                <box size="0.5 0.5 0.15"/>
            </geometry>
            <material name="white"/>
            <origin xyz="0.0 0.0 0.0" rpy="0.0 0.0 0.0"/>
        </visual>
        <collision>
            <geometry>
                <box size="0.5 0.5 0.15"/>
            </geometry>
            <origin xyz="0.0 0.0 0.0" rpy="0.0 0.0 0.0"/>
        </collision>
        <xacro:inertial_box mass="5" x="0.5" y="0.5" z="0.15" />
    </link>

    <joint name="chassis_joint" type="fixed">
        <origin xyz="0 0 0" rpy="0 0 0" />
        <parent link="base_link" />
        <child link="chassis_link" />
        <axis xyz="0 0 0" />
    </joint>

    <gazebo reference="chassis_link">
      <material>Gazebo/Orange</material>
    </gazebo>

    <!--RIGHT WHEEL-->
    <link name="right_wheel">
        <visual>
            <geometry>
                <cylinder radius="0.06" length="0.075"/>
            </geometry>
            <material name="black"/>
            <origin rpy="1.5708 0 0" xyz="0 0 0"/>
        </visual>
        <collision>
            <geometry>
            <cylinder radius="0.06" length="0.075"/>
            </geometry>
            <origin rpy="1.5708 0 0" xyz="0 0 0"/>
        </collision>
        <xacro:inertial_cylinder mass="0.2" length="0.075" radius="0.06" />
    </link>
      
    <joint name="right_wheel_joint" type="continuous">
        <origin xyz="0.13 0.2875 -0.09" rpy="0 0 0" />
        <parent link="base_link" />
        <child link="right_wheel" />
        <axis xyz="0 1 0" />
    </joint>

    <gazebo reference="right_wheel">
      <material>Gazebo/Black</material>
    </gazebo>
    
    <!--LEFHT WHEEL-->
    <link name="left_wheel">
        <visual>
            <geometry>
                <cylinder radius="0.06" length="0.075"/>
            </geometry>
            <material name="black"/>
            <origin rpy="1.5708 0 0" xyz="0 0 0"/>
        </visual>
        <collision>
            <origin rpy="1.5708 0 0" xyz="0 0 0"/>
            <geometry>
                <cylinder radius="0.06" length="0.075"/>
            </geometry>
        </collision>
        <xacro:inertial_cylinder mass="0.2" length="0.075" radius="0.06" />
    </link>
      
    <joint name="left_wheel_joint" type="continuous">
        <origin xyz="0.13 -0.2875 -0.09" rpy="0 0 0" />
        <parent link="base_link" />
        <child link="left_wheel" />
        <axis xyz="0 1 0" />
    </joint>

    <gazebo reference="left_wheel">
      <material>Gazebo/Black</material>
    </gazebo>

    <!--LIGHT TUBE-->
    <link name="light_tube">
        <visual>
            <geometry>
                <box size="0.1 0.1 1.0"/>
            </geometry>
            <material name="blue"/>
            <origin rpy="0 0 0" xyz="0 0 0"/>
        </visual>
        <collision>
            <origin rpy="0 0 0" xyz="0 0 0"/>
            <geometry>
                <box size="0.1 0.1 1.0"/>
            </geometry>
        </collision>
        <xacro:inertial_box mass="3" x="0.1" y="0.1" z="1.0" />
    </link>
      
    <joint name="light_tube_joint" type="fixed">
        <origin xyz="0.0 0.0 0.575" rpy="0 0 0" />
        <parent link="chassis_link" />
        <child link="light_tube" />
        <axis xyz="0 0 0" />
    </joint>
    
    <gazebo reference="light_tube">
      <material>Gazebo/Blue</material>
    </gazebo>
    
    <!--CASTER_WHEEL-->
    <link name="caster_wheel">
        <visual>
            <geometry>
                <sphere radius="0.035"/>
            </geometry>
            <material name="green"/>
            <origin rpy="0 0 0" xyz="0 0 0"/>
        </visual>
        <collision>
            <origin rpy="0 0 0" xyz="0 0 0"/>
            <geometry>
                <sphere radius="0.035"/>
            </geometry>
        </collision>
        <xacro:inertial_sphere mass="0.1" radius="0.035" />
    </link>
      
    <joint name="caster_wheel_joint" type="fixed">
        <origin xyz="-0.25 0 -0.110" rpy="0 0 0" />
        <parent link="chassis_link" />
        <child link="caster_wheel" />
        <axis xyz="0 0 0" />
    </joint>

    <gazebo reference="caster_wheel">
        <material>Gazebo/Green</material>
        <mu1 value="0.001"/>
        <mu2 value="0.001"/>
    </gazebo>

    <!--RPLIDAR-->
    <link name="laser_frame">
        <visual>
            <geometry>
                <cylinder radius="0.035" length="0.055"/>
            </geometry>
            <material name="red"/>
            <origin xyz="0 0 0"/>
        </visual>
        <collision>
            <geometry>
                <cylinder radius="0.035" length="0.055"/>
            </geometry>
        </collision>
        <xacro:inertial_cylinder mass="0.1" length="0.055" radius="0.035" />
    </link>

    <joint name="laser_joint" type="fixed">
        <parent link="chassis_link"/>
        <child link="laser_frame"/>
        <origin xyz="0.195 0 0.1025" rpy="0 0 0"/>
    </joint>

    <gazebo reference="laser_frame">
        <material>Gazebo/Red</material>
        <sensor name="laser" type="ray">
            <pose> 0 0 0 0 0 0 </pose>
            <visualize>true</visualize>
            <update_rate>10</update_rate>
            <ray>
                <scan>
                    <horizontal>
                        <samples>360</samples>
                        <min_angle>-3.14159</min_angle>
                        <max_angle>3.14159</max_angle>
                    </horizontal>
                </scan>
                <range>
                    <min>0.3</min>
                    <max>12</max>
                </range>
            </ray>
            <plugin name="laser_controller" filename="libgazebo_ros_laser.so">
                <!--<ros>
                    <argument>~/out:=scan</argument>
                </ros>-->
                <topicName>/scan</topicName>
                <!--<output_type>sensor_msgs/LaserScan</output_type>-->
                <frameName>laser_frame</frameName>
            </plugin>
        </sensor>  
    </gazebo>

</robot>